Failure # 1 (occurred at 2021-08-16_16-22-13)
Traceback (most recent call last):
  File "/home/sjtuer/anaconda3/envs/torch/lib/python3.7/site-packages/ray/tune/trial_runner.py", line 739, in _process_trial
    results = self.trial_executor.fetch_result(trial)
  File "/home/sjtuer/anaconda3/envs/torch/lib/python3.7/site-packages/ray/tune/ray_trial_executor.py", line 729, in fetch_result
    result = ray.get(trial_future[0], timeout=DEFAULT_GET_TIMEOUT)
  File "/home/sjtuer/anaconda3/envs/torch/lib/python3.7/site-packages/ray/_private/client_mode_hook.py", line 82, in wrapper
    return func(*args, **kwargs)
  File "/home/sjtuer/anaconda3/envs/torch/lib/python3.7/site-packages/ray/worker.py", line 1564, in get
    raise value.as_instanceof_cause()
ray.exceptions.RayTaskError(ValueError): [36mray::CCPPOTrainer.train_buffered()[39m (pid=20307, ip=10.131.0.34)
  File "python/ray/_raylet.pyx", line 534, in ray._raylet.execute_task
  File "python/ray/_raylet.pyx", line 484, in ray._raylet.execute_task.function_executor
  File "/home/sjtuer/anaconda3/envs/torch/lib/python3.7/site-packages/ray/_private/function_manager.py", line 563, in actor_method_executor
    return method(__ray_actor, *args, **kwargs)
  File "/home/sjtuer/anaconda3/envs/torch/lib/python3.7/site-packages/ray/tune/trainable.py", line 178, in train_buffered
    result = self.train()
  File "/home/sjtuer/anaconda3/envs/torch/lib/python3.7/site-packages/ray/rllib/agents/trainer.py", line 643, in train
    raise e
  File "/home/sjtuer/anaconda3/envs/torch/lib/python3.7/site-packages/ray/rllib/agents/trainer.py", line 629, in train
    result = Trainable.train(self)
  File "/home/sjtuer/anaconda3/envs/torch/lib/python3.7/site-packages/ray/tune/trainable.py", line 237, in train
    result = self.step()
  File "/home/sjtuer/anaconda3/envs/torch/lib/python3.7/site-packages/ray/rllib/agents/trainer_template.py", line 170, in step
    res = next(self.train_exec_impl)
  File "/home/sjtuer/anaconda3/envs/torch/lib/python3.7/site-packages/ray/util/iter.py", line 756, in __next__
    return next(self.built_iterator)
  File "/home/sjtuer/anaconda3/envs/torch/lib/python3.7/site-packages/ray/util/iter.py", line 783, in apply_foreach
    for item in it:
  File "/home/sjtuer/anaconda3/envs/torch/lib/python3.7/site-packages/ray/util/iter.py", line 783, in apply_foreach
    for item in it:
  File "/home/sjtuer/anaconda3/envs/torch/lib/python3.7/site-packages/ray/util/iter.py", line 843, in apply_filter
    for item in it:
  File "/home/sjtuer/anaconda3/envs/torch/lib/python3.7/site-packages/ray/util/iter.py", line 843, in apply_filter
    for item in it:
  File "/home/sjtuer/anaconda3/envs/torch/lib/python3.7/site-packages/ray/util/iter.py", line 783, in apply_foreach
    for item in it:
  File "/home/sjtuer/anaconda3/envs/torch/lib/python3.7/site-packages/ray/util/iter.py", line 783, in apply_foreach
    for item in it:
  File "/home/sjtuer/anaconda3/envs/torch/lib/python3.7/site-packages/ray/util/iter.py", line 783, in apply_foreach
    for item in it:
  [Previous line repeated 1 more time]
  File "/home/sjtuer/anaconda3/envs/torch/lib/python3.7/site-packages/ray/util/iter.py", line 876, in apply_flatten
    for item in it:
  File "/home/sjtuer/anaconda3/envs/torch/lib/python3.7/site-packages/ray/util/iter.py", line 828, in add_wait_hooks
    item = next(it)
  File "/home/sjtuer/anaconda3/envs/torch/lib/python3.7/site-packages/ray/util/iter.py", line 791, in apply_foreach
    result = fn(item)
  File "/home/sjtuer/anaconda3/envs/torch/lib/python3.7/site-packages/ray/rllib/execution/rollout_ops.py", line 186, in __call__
    out = SampleBatch.concat_samples(self.buffer)
  File "/home/sjtuer/anaconda3/envs/torch/lib/python3.7/site-packages/ray/rllib/policy/sample_batch.py", line 158, in concat_samples
    time_major=concat_samples[0].time_major)
  File "/home/sjtuer/anaconda3/envs/torch/lib/python3.7/site-packages/ray/rllib/utils/memory.py", line 68, in concat_aligned
    output = flat.reshape(new_shape)
ValueError: cannot reshape array of size 108 into shape (36,4)

